<mujoco model="ur10e scene">
  <compiler angle="radian" meshdir="assets/" autolimits="true"/>
  <option integrator="implicitfast"/>
  <size nkey="1"/>
  <visual>
    <global azimuth="120" elevation="-20"/>
    <headlight diffuse="0.6 0.6 0.6" specular="0 0 0"/>
    <rgba haze="0.15 0.25 0.35 1"/>
  </visual>
  <statistic meansize="0.263575" extent="1" center="0.4 0 0.4"/>
  <default class="main">
    <default class="ur10e">
      <material shininess="0.25"/>
      <joint range="-6.28319 6.28319" armature="0.1"/>
      <site size="0.001 0.005 0.005" group="4" rgba="0.5 0.5 0.5 0.3"/>
      <general ctrlrange="-6.2831 6.2831" biastype="affine" gainprm="5000 0 0 0 0 0 0 0 0 0" biasprm="0 -5000 -500 0 0 0 0 0 0 0"/>
      <default class="size4">
        <joint damping="10"/>
        <general forcerange="-330 330"/>
      </default>
      <default class="size3">
        <joint damping="5"/>
        <general forcerange="-150 150"/>
        <default class="size3_limited">
          <joint range="-3.1415 3.1415"/>
          <general ctrlrange="-3.1415 3.1415"/>
        </default>
      </default>
      <default class="size2">
        <joint damping="2"/>
        <general forcerange="-56 56"/>
      </default>
      <default class="visual">
        <geom type="mesh" contype="0" conaffinity="0" group="2"/>
      </default>
      <default class="collision">
        <geom type="capsule" group="3"/>
        <default class="eef_collision">
          <geom type="cylinder"/>
        </default>
      </default>
    </default>
  </default>
  <asset>
    <texture type="skybox" builtin="gradient" rgb1="0.3 0.5 0.7" rgb2="0 0 0" width="512" height="3072"/>
    <texture type="2d" name="groundplane" builtin="checker" mark="edge" rgb1="0.2 0.3 0.4" rgb2="0.1 0.2 0.3" markrgb="0.8 0.8 0.8" width="300" height="300"/>
    <material name="black" class="ur10e" rgba="0.033 0.033 0.033 1"/>
    <material name="jointgray" class="ur10e" rgba="0.278 0.278 0.278 1"/>
    <material name="linkgray" class="ur10e" rgba="0.82 0.82 0.82 1"/>
    <material name="urblue" class="ur10e" rgba="0.49 0.678 0.8 1"/>
    <material name="groundplane" texture="groundplane" texuniform="true" texrepeat="5 5" reflectance="0.2"/>
    <mesh name="base_0" file="base_0.obj"/>
    <mesh name="base_1" file="base_1.obj"/>
    <mesh name="shoulder_0" file="shoulder_0.obj"/>
    <mesh name="shoulder_1" file="shoulder_1.obj"/>
    <mesh name="shoulder_2" file="shoulder_2.obj"/>
    <mesh name="upperarm_0" file="upperarm_0.obj"/>
    <mesh name="upperarm_1" file="upperarm_1.obj"/>
    <mesh name="upperarm_2" file="upperarm_2.obj"/>
    <mesh name="upperarm_3" file="upperarm_3.obj"/>
    <mesh name="forearm_0" file="forearm_0.obj"/>
    <mesh name="forearm_1" file="forearm_1.obj"/>
    <mesh name="forearm_2" file="forearm_2.obj"/>
    <mesh name="forearm_3" file="forearm_3.obj"/>
    <mesh name="wrist1_0" file="wrist1_0.obj"/>
    <mesh name="wrist1_1" file="wrist1_1.obj"/>
    <mesh name="wrist1_2" file="wrist1_2.obj"/>
    <mesh name="wrist2_0" file="wrist2_0.obj"/>
    <mesh name="wrist2_1" file="wrist2_1.obj"/>
    <mesh name="wrist2_2" file="wrist2_2.obj"/>
    <mesh name="wrist3" file="wrist3.obj"/>
  </asset>
  <worldbody>
    <geom name="floor" size="0 0 0.05" type="plane" material="groundplane"/>
    <light name="spotlight" target="wrist_2_link" pos="0 -1 2" dir="0 0 -1" mode="targetbodycom"/>
    <light pos="0 0 1.5" dir="0 0 -1" directional="true"/>
    <body name="base" childclass="ur10e" quat="0.707107 0 0 0.707107">
      <inertial pos="0 0 0" mass="4" diaginertia="0.00610633 0.00610633 0.01125"/>
      <geom class="visual" material="black" mesh="base_0"/>
      <geom class="visual" material="jointgray" mesh="base_1"/>
      <body name="shoulder_link" pos="0 0 0.181">
        <inertial pos="0 0 0" mass="7.778" diaginertia="0.0314743 0.0314743 0.0218756"/>
        <joint name="shoulder_pan_joint" class="size4" pos="0 0 0" axis="0 0 1"/>
        <geom class="visual" material="urblue" mesh="shoulder_0"/>
        <geom class="visual" material="black" mesh="shoulder_1"/>
        <geom class="visual" material="jointgray" mesh="shoulder_2"/>
        <geom class="collision" size="0.078 0.08" pos="0 0 -0.05"/>
        <body name="upper_arm_link" pos="0 0.176 0" quat="0.707107 0 0.707107 0">
          <inertial pos="0 0 0.3065" mass="12.93" diaginertia="0.423074 0.423074 0.0363656"/>
          <joint name="shoulder_lift_joint" class="size4" pos="0 0 0" axis="0 1 0"/>
          <geom class="visual" material="black" mesh="upperarm_0"/>
          <geom class="visual" material="jointgray" mesh="upperarm_1"/>
          <geom class="visual" material="urblue" mesh="upperarm_2"/>
          <geom class="visual" material="linkgray" mesh="upperarm_3"/>
          <geom class="collision" size="0.078 0.08" pos="0 -0.05 0" quat="0.707107 0.707107 0 0"/>
          <geom class="collision" size="0.06 0.3" pos="0 0 0.3"/>
          <body name="forearm_link" pos="0 -0.137 0.613">
            <inertial pos="0 0 0.2855" mass="3.87" diaginertia="0.11059 0.11059 0.0108844"/>
            <joint name="elbow_joint" class="size3_limited" pos="0 0 0" axis="0 1 0"/>
            <geom class="visual" material="urblue" mesh="forearm_0"/>
            <geom class="visual" material="black" mesh="forearm_1"/>
            <geom class="visual" material="jointgray" mesh="forearm_2"/>
            <geom class="visual" material="linkgray" mesh="forearm_3"/>
            <geom class="collision" size="0.058 0.065" pos="0 0.08 0" quat="0.707107 0.707107 0 0"/>
            <geom class="collision" size="0.043 0.28" pos="0 0 0.29"/>
            <body name="wrist_1_link" pos="0 0 0.571" quat="0.707107 0 0.707107 0">
              <inertial pos="0 0.135 0" quat="0.5 0.5 -0.5 0.5" mass="1.96" diaginertia="0.0055125 0.00510825 0.00510825"/>
              <joint name="wrist_1_joint" class="size2" pos="0 0 0" axis="0 1 0"/>
              <geom class="visual" material="black" mesh="wrist1_0"/>
              <geom class="visual" material="urblue" mesh="wrist1_1"/>
              <geom class="visual" material="jointgray" mesh="wrist1_2"/>
              <geom class="collision" size="0.05 0.07" pos="0 0.06 0" quat="0.707107 0.707107 0 0"/>
              <body name="wrist_2_link" pos="0 0.135 0">
                <inertial pos="0 0 0.12" quat="0.5 0.5 -0.5 0.5" mass="1.96" diaginertia="0.0055125 0.00510825 0.00510825"/>
                <joint name="wrist_2_joint" class="size2" pos="0 0 0" axis="0 0 1"/>
                <geom class="visual" material="black" mesh="wrist2_0"/>
                <geom class="visual" material="urblue" mesh="wrist2_1"/>
                <geom class="visual" material="jointgray" mesh="wrist2_2"/>
                <geom class="collision" size="0.046 0.065" pos="0 0 0.05"/>
                <geom class="collision" size="0.046 0.043" pos="0 0.028 0.12" quat="0.707107 0.707107 0 0"/>
                <body name="wrist_3_link" pos="0 0 0.12">
                  <inertial pos="0 0.092 0" quat="0 0.707107 -0.707107 0" mass="0.202" diaginertia="0.000204525 0.000144346 0.000144346"/>
                  <joint name="wrist_3_joint" class="size2" pos="0 0 0" axis="0 1 0"/>
                  <geom class="visual" material="linkgray" mesh="wrist3"/>
                  <geom class="eef_collision" size="0.046 0.02" pos="0 0.097 0" quat="0.707107 0.707107 0 0"/>
                  <site name="attachment_site" pos="0 0.1 0" quat="-0.707107 0.707107 0 0"/>
                </body>
              </body>
            </body>
          </body>
        </body>
      </body>
    </body>
  </worldbody>
  <actuator>
    <general name="shoulder_pan" class="size4" joint="shoulder_pan_joint"/>
    <general name="shoulder_lift" class="size4" joint="shoulder_lift_joint"/>
    <general name="elbow" class="size3_limited" joint="elbow_joint"/>
    <general name="wrist_1" class="size2" joint="wrist_1_joint"/>
    <general name="wrist_2" class="size2" joint="wrist_2_joint"/>
    <general name="wrist_3" class="size2" joint="wrist_3_joint"/>
  </actuator>
  <keyframe>
    <key name="home" qpos="-1.5708 -1.5708 1.5708 -1.5708 -1.5708 0" ctrl="-1.5708 -1.5708 1.5708 -1.5708 -1.5708 0"/>
  </keyframe>
</mujoco>
